Workbook
Name IQ_CH: 110000
Name IQ_CQ: 5000
Name IQ_CY: 10000
Name IQ_DAILY: 500000
Name IQ_FH: 100000
Name IQ_FQ: 500
Name IQ_FWD_CY: 10001
Name IQ_FWD_CY1: 10002
Name IQ_FWD_CY2: 10003
Name IQ_FWD_FY: 1001
Name IQ_FWD_FY1: 1002
Name IQ_FWD_FY2: 1003
Name IQ_FWD_Q: 501
Name IQ_FWD_Q1: 502
Name IQ_FWD_Q2: 503
Name IQ_FY: 1000
Name IQ_LATESTK: 1000
Name IQ_LATESTQ: 500
Name IQ_LTM: 2000
Name IQ_LTMMONTH: 120000
Name IQ_MONTH: 15000
Name IQ_NTM: 6000
Name IQ_TODAY: 0
Name IQ_WEEK: 50000
Name IQ_YTD: 3000
Name IQ_YTDMONTH: 130000

Sheet Dashboard
B1: Sustainability Dashboard
B3: Energy Consumption in kWh (by source) April to July 2025
B21: Waste recovered through recycling, and re-using (in kgs) April to August 2025
B40: ='Data for dashboard'!B9 -> Water Consumption (by source in Kilo Ltrs)

Sheet Data for dashboard
B1: SPJIMR Environmental Metrics | C1: Particular | D1: Apr'25 | E1: May'25 | F1: Jun'25 | G1: Jul'25 | H1: Aug'25 | I1: Sep'25 | J1: Oct'25 | K1: Nov'25 | L1: Dec'25 | M1: Jan'26 | N1: Feb'26 | O1: Mar'26 | P1: Total | Q1: %
A2: 1 | B2: Energy Consumption in kWh (by source) | C2: Renewable Sources - Solar | D2: ='Data Sheet'!D6 -> 6669 | E2: ='Data Sheet'!E6 -> 5754 | F2: ='Data Sheet'!F6 -> 4679 | G2: ='Data Sheet'!G6 -> 3794 | H2: ='Data Sheet'!H6 -> 3465.9 | I2: ='Data Sheet'!I6 -> 1662 | J2: ='Data Sheet'!J6 -> 2065 | K2: ='Data Sheet'!K6 -> 1984 | ... O2: ='Data Sheet'!O6 | P2: =SUM(D2:O2) -> 31694.9 | Q2: =P2/$P$5 -> 0.012646072
C3: Renewable Sources - Adani | D3: ='Data Sheet'!D7 | E3: ='Data Sheet'!E7 | F3: ='Data Sheet'!F7 -> 310650 | G3: ='Data Sheet'!G7 -> 335257 | H3: ='Data Sheet'!H7 -> 307939 | I3: ='Data Sheet'!I7 -> 264430 | J3: ='Data Sheet'!J7 -> 246046 | K3: ='Data Sheet'!K7 -> 275686 | ... O3: ='Data Sheet'!O7 | P3: =SUM(D3:O3) -> 1967726 | Q3: =P3/$P$5 -> 0.7851107
C4: Non-Renewable Sources | D4: ='Data Sheet'!D9 -> 251707 | E4: ='Data Sheet'!E9 -> 249662 | F4: ='Data Sheet'!F9 -> 5514 | G4: ='Data Sheet'!G9 -> 0 | H4: ='Data Sheet'!H9 -> 0 | I4: ='Data Sheet'!I9 -> 0 | J4: ='Data Sheet'!J9 -> 0 | K4: ='Data Sheet'!K9 -> 0 | ... O4: ='Data Sheet'!O9 | P4: =SUM(D4:O4) -> 506883 | Q4: =P4/$P$5 -> 0.20224323
C5: Total Energy Consumed (in kWh) | D5: =SUM(D2:D4) -> 258376 | E5: =SUM(E2:E4) -> 255416 | F5: =SUM(F2:F4) -> 320843 | G5: =SUM(G2:G4) -> 339051 | H5: =SUM(H2:H4) -> 311404.9 | I5: =SUM(I2:I4) -> 266092 | J5: =SUM(J2:J4) -> 248111 | K5: =SUM(K2:K4) -> 277670 | ... P5: =SUM(P2:P4) -> 2506303.9 | Q5: =P5/$P$5 -> 1
C6: Energy Mix (Renewable as %age of Total) | D6: =SUM(D2:D3)/D5 -> 0.025811221 | E6: =SUM(E2:E3)/E5 -> 0.022527954 | F6: =SUM(F2:F3)/F5 -> 0.98281402 | G6: =SUM(G2:G3)/G5 -> 1 | H6: =SUM(H2:H3)/H5 -> 1 | I6: =SUM(I2:I3)/I5 -> 1 | J6: =SUM(J2:J3)/J5 -> 1 | K6: =SUM(K2:K3)/K5 -> 1 | ... O6: =SUM(O2:O3)/O5 -> #DIV/0!
A9: 2 | B9: Water Consumption (by source in Kilo Ltrs)
B10: SPJIMR Environmental Metrics | C10: Particular | D10: Apr'25 | E10: May'25 | F10: Jun'25 | G10: Jul'25 | H10: Aug'25 | I10: Sep'25 | J10: Oct'25 | K10: Nov'25 | L10: Dec'25 | M10: Jan'26 | N10: Feb'26 | O10: Mar'26 | P10: Total | Q10: %
C11: Municipal Corporation | D11: ='Data Sheet'!D15 -> 2691 | E11: ='Data Sheet'!E15 -> 2482 | F11: ='Data Sheet'!F15 -> 3125 | G11: ='Data Sheet'!G15 -> 3097 | H11: ='Data Sheet'!H15 -> 11130 | I11: ='Data Sheet'!I15 -> 8011 | J11: ='Data Sheet'!J15 -> 6214 | K11: ='Data Sheet'!K15 -> 3021 | ... O11: ='Data Sheet'!O15 | P11: =SUM(D11:O11) -> 42475 | Q11: =P11/$P$14 -> 0.85084621
C12: Tanker | D12: ='Data Sheet'!D16 -> 60 | E12: ='Data Sheet'!E16 -> 140 | F12: ='Data Sheet'!F16 -> 540 | G12: ='Data Sheet'!G16 -> 740 | H12: ='Data Sheet'!H16 -> 500 | I12: ='Data Sheet'!I16 -> 770 | J12: ='Data Sheet'!J16 -> 620 | K12: ='Data Sheet'!K16 -> 1120 | ... O12: ='Data Sheet'!O16 | P12: =SUM(D12:O12) -> 6210 | Q12: =P12/$P$14 -> 0.12439682
C13: Rainwater Harvesting | D13: ='Data Sheet'!D17 | E13: ='Data Sheet'!E17 | F13: ='Data Sheet'!F17 | G13: ='Data Sheet'!G17 | H13: ='Data Sheet'!H17 -> 303.32 | I13: ='Data Sheet'!I17 -> 210.57 | J13: ='Data Sheet'!J17 -> 188 | K13: ='Data Sheet'!K17 -> 245 | ... O13: ='Data Sheet'!O17 | P13: =SUM(D13:O13) -> 1235.89 | Q13: =P13/$P$14 -> 0.02475697
C14: Total Water Consumed (in kiloliters) | D14: =SUM(D11:D13) -> 2751 | E14: =SUM(E11:E13) -> 2622 | F14: =SUM(F11:F13) -> 3665 | G14: =SUM(G11:G13) -> 3837 | H14: =SUM(H11:H13) -> 11933.32 | I14: =SUM(I11:I13) -> 8991.57 | J14: =SUM(J11:J13) -> 7022 | K14: =SUM(K11:K13) -> 4386 | ... P14: =SUM(P11:P13) -> 49920.89 | Q14: =P14/$P$14 -> 1
A16: 3 | B16: Waste recovered through recycling, and re-using (in kgs) | C16: Particular | D16: Apr'25 | E16: May'25 | F16: Jun'25 | G16: Jul'25 | H16: Aug'25 | I16: Sep'25 | J16: Oct'25 | K16: Nov'25 | L16: Dec'25 | M16: Jan'26 | N16: Feb'26 | O16: Mar'26 | P16: Total | Q16: %
C17: Waste recovered | D17: ='Data Sheet'!D36 -> 2438 | E17: ='Data Sheet'!E36 -> 3453 | F17: ='Data Sheet'!F36 -> 3658.5 | G17: ='Data Sheet'!G36 -> 3983 | H17: ='Data Sheet'!H36 -> 4042 | I17: ='Data Sheet'!I36 -> 4545 | J17: ='Data Sheet'!J36 -> 6786 | K17: ='Data Sheet'!K36 -> 8911 | ... O17: ='Data Sheet'!O36 -> 0 | P17: =SUM(D17:O17) -> 57601.5 | Q17: =P17/$P$19 -> 0.38422773
C18: waste disposed off | D18: ='Data Sheet'!D44 -> 16515 | E18: ='Data Sheet'!E44 -> 13401 | F18: ='Data Sheet'!F44 -> 12682.5 | G18: ='Data Sheet'!G44 -> 14412 | H18: ='Data Sheet'!H44 -> 11238 | I18: ='Data Sheet'!I44 -> 12263 | J18: ='Data Sheet'!J44 -> 3047 | K18: ='Data Sheet'!K44 -> 2560 | ... O18: ='Data Sheet'!O44 | P18: =SUM(D18:O18) -> 92313.5 | Q18: =P18/$P$19 -> 0.61577227
C19: Total waste | D19: =D17+D18 -> 18953 | E19: =E17+E18 -> 16854 | F19: =F17+F18 -> 16341 | G19: =G17+G18 -> 18395 | H19: =H17+H18 -> 15280 | I19: =I17+I18 -> 16808 | J19: =J17+J18 -> 9833 | K19: =K17+K18 -> 11471 | ... O19: =O17+O18 -> 0 | P19: =P18+P17 -> 149915 | Q19: =P19/$P$19 -> 1
C20: % Waste Recovered | D20: =D17/D19 -> 0.12863399 | E20: =E17/E19 -> 0.20487718 | F20: =F17/F19 -> 0.22388471 | G20: =G17/G19 -> 0.21652623 | H20: =H17/H19 -> 0.2645288 | I20: =I17/I19 -> 0.27040695 | J20: =J17/J19 -> 0.69012509 | K20: =K17/K19 -> 0.77682852 | ... Q20: =Q17/Q19 -> 0.38422773

Sheet Data Sheet
A1: ESG Dashboard Draft Template
D2: Apr'25 | E2: May'25 | F2: Jun'25 | G2: Jul'25 | H2: Aug'25 | I2: Sep'25 | J2: Oct'25 | K2: Nov'25 | L2: Dec'25 | M2: Jan'26 | N2: Feb'26 | O2: Mar'26 | P2: Data Owner
A3: SPJIMR Environmental Metrics
A4: 1 | B4: Energy Consumption in kWh (by source) | P4: Jayesh
B5: From Renewable Sources
C6: Solar (LH) | D6: 6669 | E6: 5754 | F6: 4679 | G6: 3794 | H6: 3465.9 | I6: 1662 | J6: 2065 | K6: 1984 | L6: 1622 | R6: Apr'25 | S6: 6669 | T6: 315329 | U6: 251707
C7: Adani Green | F7: =315329-F6 -> 310650 | G7: =339051-G6 -> 335257 | H7: 307939 | I7: 264430 | J7: 246046 | K7: 275686 | L7: 227718 | R7: May'25 | S7: 5754 | T7: 339051 | U7: 249662
B8: From Non-Renewable Sources | R8: Jun'25 | S8: 4679 | U8: 5514
C9: Adani | D9: 251707 | E9: 249662 | F9: 5514 | G9: 0 | H9: 0 | I9: 0 | J9: 0 | K9: 0 | L9: 0 | R9: Jul'25 | S9: 3794 | U9: 0
C10: Diesel Generators' Output | R10: Aug'25
B11: Total Energy Consumed (in kWh) | D11: =SUM(D6:D10) -> 258376 | E11: =SUM(E6:E10) -> 255416 | F11: =SUM(F6:F10) -> 320843 | G11: =SUM(G6:G10) -> 339051 | H11: =SUM(H6:H10) -> 311404.9 | I11: =SUM(I6:I10) -> 266092 | J11: =SUM(J6:J10) -> 248111 | K11: =SUM(K6:K10) -> 277670 | ... O11: =SUM(O6:O10) -> 0 | R11: Sep'25
B12: Energy Mix (Renewable as %age of Total) | D12: =SUM(D6:D7)/D11 -> 0.025811221 | E12: =SUM(E6:E7)/E11 -> 0.022527954 | F12: =SUM(F6:F7)/F11 -> 0.98281402 | G12: =SUM(G6:G7)/G11 -> 1 | H12: =SUM(H6:H7)/H11 -> 1 | I12: =SUM(I6:I7)/I11 -> 1 | J12: =SUM(J6:J7)/J11 -> 1 | K12: =SUM(K6:K7)/K11 -> 1 | ... O12: =SUM(O6:O7)/O11 -> #DIV/0! | R12: Oct'25
R13: Nov'25
A14: 2 | B14: Water Consumption (by source in Kilo Ltrs) | P14: Jayesh | R14: Dec'25
B15: From Municipal Corporation | D15: 2691 | E15: 2482 | F15: 3125 | G15: 3097 | H15: 11130 | I15: 8011 | J15: 6214 | K15: 3021 | L15: 2704 | R15: Jan'26
B16: From Tanker | D16: 60 | E16: 140 | F16: 540 | G16: 740 | H16: 500 | I16: 770 | J16: 620 | K16: =60+120+320+420+40+160 -> 1120 | L16: =20+60+240+260+20+100+20 -> 720 | M16: 1000 | P16: =60+100+280 -> 440 | R16: Feb'26
B17: From Rainwater Harvesting | H17: 303.32 | I17: 210.57 | J17: 188 | K17: 245 | L17: 174 | M17: 115 | R17: Mar'26
B18: Total Water Consumed (in kiloliters) | D18: =SUM(D15:D17) -> 2751 | E18: =SUM(E15:E17) -> 2622 | F18: =SUM(F15:F17) -> 3665 | G18: =SUM(G15:G17) -> 3837 | H18: =SUM(H15:H17) -> 11933.32 | I18: =SUM(I15:I17) -> 8991.57 | J18: =SUM(J15:J17) -> 7022 | K18: =SUM(K15:K17) -> 4386 | ... O18: =SUM(O15:O17) -> 0
B19: % of water consumed from renewable sources | D19: =D17/D18 -> 0 | E19: =E17/E18 -> 0 | F19: =F17/F18 -> 0 | G19: =G17/G18 -> 0 | H19: =H17/H18 -> 0.025417905 | I19: =I17/I18 -> 0.023418602 | J19: =J17/J18 -> 0.026772999 | K19: =K17/K18 -> 0.055859553 | ... O19: =O17/O18 -> #DIV/0!
A21: 3 | B21: Waste Generation by Type (kgs) | P21: Noorin
B22: Wet Waste (A) | D22: 9502 | E22: 8278 | F22: 8543 | G22: 9851 | H22: 7447 | I22: 8991 | J22: 4697 | K22: 6945 | L22: 6233 | M22: 6831
B23: Dry Waste (B) | D23: 3794 | E23: 3569 | F23: 2955 | G23: 2717 | H23: 2783 | I23: 3314 | J23: 2606 | K23: 4801 | L23: 5510 | M23: 5367
B24: Sanitary Waste (C) | F24: 150 | I24: 65 | J24: 30 | K24: 60 | L24: 52 | M24: 61
B25: E-waste Generated (D) | E25: 40 | H25: 143
B26: Personal Belongings (E) | E26: 72 | G26: 45 | H26: 40 | J26: 500 | M26: 250
B27: Reject Waste (F) | D27: 5657 | E27: 4895 | F27: 4693 | G27: 5782 | H27: 4867 | I27: 4438 | J27: 2000 | K27: 1954 | L27: 1892 | M27: 1834
B28: Total Waste Generated (in kgs) | D28: =SUM(D22:D27) -> 18953 | E28: =SUM(E22:E27) -> 16854 | F28: =SUM(F22:F27) -> 16341 | G28: =SUM(G22:G27) -> 18395 | H28: =SUM(H22:H27) -> 15280 | I28: =SUM(I22:I27) -> 16808 | J28: =SUM(J22:J27) -> 9833 | K28: =SUM(K22:K27) -> 13760 | ... O28: =SUM(O22:O27) -> 0
A30: 4 | B30: Total waste recovered through recycling, re-using or other recovery operations (in kgs) | P30: Noorin
B31: (i) Recycled Wet Waste | D31: 938 | E31: 687 | F31: 1059 | G31: 1221 | H31: 1076 | I31: 1230 | J31: 3650 | K31: 4050 | L31: 4235 | M31: 4560
B32: (ii) Recycled Dry Waste | D32: 1500 | E32: 2654 | F32: 2589 | G32: 2717 | H32: 2783 | I32: 3250 | J32: 2606 | K32: 4801 | L32: 5510 | M32: 5367
B33: (iii) Recycled E-waste | E33: 40 | H33: 143
B34: (iv) Recycled Sanitary Waste | F34: 10.5 | H34: 40 | I34: 65 | J34: 30 | K34: 60 | L34: 52 | M34: 61
B35: (v) Sent for Re-use | E35: 72 | G35: 45 | J35: 500
B36: Total Waste Recovered (in kgs) | D36: =SUM(D31:D35) -> 2438 | E36: =SUM(E31:E35) -> 3453 | F36: =SUM(F31:F35) -> 3658.5 | G36: =SUM(G31:G35) -> 3983 | H36: =SUM(H31:H35) -> 4042 | I36: =SUM(I31:I35) -> 4545 | J36: =SUM(J31:J35) -> 6786 | K36: =SUM(K31:K35) -> 8911 | ... O36: =SUM(O31:O35) -> 0
B37: Waste Recovered as % to total waste | D37: =D36/D28 -> 0.12863399 | E37: =E36/E28 -> 0.20487718 | F37: =F36/F28 -> 0.22388471 | G37: =G36/G28 -> 0.21652623 | H37: =H36/H28 -> 0.2645288 | I37: =I36/I28 -> 0.27040695 | J37: =J36/J28 -> 0.69012509 | K37: =K36/K28 -> 0.64760174 | ... O37: =O36/O28 -> #DIV/0!
A39: 5 | B39: Compost generated (In Kgs) | D39: 29 | E39: 20 | F39: 16 | G39: 39 | H39: 20 | I39: 35 | J39: 90 | K39: 95 | L39: 105 | M39: 95
A41: 6 | B41: Total waste disposed off and nature of disposal method (in kgs) | P41: Noorin
B42: (Mention category of waste)
B43: (i) BMC | D43: =D28-D36 -> 16515 | E43: =E28-E36 -> 13401 | F43: =F28-F36 -> 12682.5 | G43: =G28-G36 -> 14412 | H43: =H28-H36 -> 11238 | I43: =I28-I36 -> 12263 | J43: =J28-J36 -> 3047 | K43: 2560 | L43: 3520 | M43: 2675
B44: Total (in kgs.) | D44: =D43 -> 16515 | E44: =E43 -> 13401 | F44: =F43 -> 12682.5 | G44: =G43 -> 14412 | H44: =H43 -> 11238 | I44: =I43 -> 12263 | J44: =J43 -> 3047 | K44: =K43 -> 2560 | ... O44: =O43
...
